import time
import logging

class SystemCoordinator:
    def __init__(self, max_iterations: int, num_agents: int):
        self.max_iterations = max_iterations
        self.num_agents = num_agents
        self.logger = logging.getLogger(__name__)
    
    def execute_agents_parallel(self):
        # Placeholder for the actual parallel execution logic
        # This should return a list of results from the agents
        pass
    
    def execute_iteration(self, iteration_num: int):
        """反復実行を行う"""
        try:
            self.logger.info(f"反復 {iteration_num}/{self.max_iterations} を開始")
            
            # エージェント並列実行
            start_time = time.time()
            results = self.execute_agents_parallel()
            execution_time = time.time() - start_time
            
            self.logger.info(f"プロセスベース並列実行完了: {execution_time:.2f}秒")
            
            # 結果の検証と処理
            successful_results = [r for r in results if r is not None and 'error' not in r]
            success_rate = len(successful_results) / len(results) if results else 0
            
            self.logger.info(f"成功率 {success_rate*100:.2f}% ({len(successful_results)}/{len(results)})")
            
            # 並列効率の計算
            theoretical_time = execution_time * len(results)
            parallel_efficiency = (theoretical_time / (execution_time * self.num_agents)) if execution_time > 0 else 0
            self.logger.info(f"並列効率: {parallel_efficiency*100:.2f}%")
            
            # エラーが多い場合の警告
            if success_rate < 0.5:
                self.logger.warning(f"反復 {iteration_num} でエージェント実行に問題が発生しました")
                # エラーの詳細をログに出力
                for i, result in enumerate(results):
                    if result is None or 'error' in result:
                        error_msg = result.get('error', 'Unknown error') if result else 'No result returned'
                        self.logger.error(f"エージェント {i+1} エラー: {error_msg}")
            
            return successful_results
            
        except Exception as e:
            self.logger.error(f"反復 {iteration_num} 実行中にエラーが発生: {e}")
            return []